Workbook

Sheet preg1-Norma
A2: Tecnología | B2: filtro | C2: Localización | D2: Pot Exis MW | E2: Pot Nueva MW | F2: Gen GWh | G2: Pot total MW
A3: bio | B3: fil64 | C3: Ita | D3: 60 | E3: 0 | F3: 289.01 | G3: =+D3+E3 -> 60
A4: bio | B4: fil64 | C4: Cha | D4: 204 | E4: 0 | F4: 982.63 | G4: =+D4+E4 -> 204
A5: car | B5: fil60 | C5: Hua | D5: 575 | E5: 0 | F5: 4432.56 | G5: =+D5+E5 -> 575
A6: car | B6: fil60 | C6: Qui | D6: 812 | E6: 852.48 | F6: 10395.9 | G6: =+D6+E6 -> 1664.48
A7: car | B7: fil60 | C7: Cor | D7: 806 | E7: 0 | F7: 6142.69 | G7: =+D7+E7 -> 806
A8: gas | B8: fil22 | C8: Qui | D8: 731 | E8: 0 | F8: 3397.68 | G8: =+D8+E8 -> 731
A9: die | B9: fil53 | C9: car | D9: 169 | E9: 0 | F9: 182.52 | G9: =+D9+E9 -> 169
A10: die | B10: fil53 | C10: LVi | D10: 203 | E10: 0 | F10: 107.18 | G10: =+D10+E10 -> 203
A11: die | B11: fil53 | C11: Qui | D11: 700 | E11: 0 | F11: 772.8 | G11: =+D11+E11 -> 700
A12: die | B12: fil53 | C12: RMe | D12: 233.44 | E12: 0 | F12: 254.92 | G12: =+D12+E12 -> 233.44
A13: die | B13: fil53 | C13: Cha | D13: 1043 | E13: 0 | F13: 1151.47 | G13: =+D13+E13 -> 1043
A14: die | B14: fil53 | C14: Val | D14: 135 | E14: 0 | F14: 145.8 | G14: =+D14+E14 -> 135
... A22: hid | B22: fil64 | C22: Cha | D22: 5571 | E22: 1500 | F22: 37165.18 | G22: =+D22+E22 -> 7071
A23: eo1 | B23: fil64 | C23: LVi | D23: 192 | E23: 0 | F23: 420.48 | G23: =+D23+E23 -> 192 | J23: 27174.34 | K23: =D28/J23 -> 0.75425677
A24: so1 | B24: fil64 | C24: Hua | D24: 200 | E24: 0 | F24: 438 | G24: =+D24+E24 -> 200
F25: =+SUM(F3:F24) -> 66428.94 | G25: =+SUM(G3:G24) -> 15059.48
A27: mp Miles Ton | B27: sox Miles Ton | C27: nox Miles Ton | D27: co2 Miles Ton
A28: 2.49 | B28: 22.29 | C28: 94.24 | D28: 20496.43
A29: mp US$ | B29: sox US$ | C29: nox US$ | D29: co2 US$ | E29: Costo total US$ (no incluye daño ambiental)
A30: 6023168.3 | B30: 21052237 | C30: 1.4596391e+08 | D30: 0 | E30: 2293628900
F34: Gen GWh | G34: Pot total MW
A35: Biomasa | F35: =+F3+F4 -> 1271.64 | G35: =+G3+G4 -> 264
A36: Carbón | F36: =+SUM(F5:F7) -> 20971.15 | G36: =+SUM(G5:G7) -> 3045.48
A37: CC-GNL | F37: =+F8 -> 3397.68 | G37: =+G8 -> 731
A38: Petróleo Diesel | F38: =+SUM(F9:F21) -> 2764.81 | G38: =+SUM(G9:G21) -> 3556
A39: Hidro | F39: =+F22 -> 37165.18 | G39: =+G22 -> 7071
A40: Eolica | F40: =+F23 -> 420.48 | G40: =+G23 -> 192
A41: Solar | F41: =+F24 -> 438 | G41: =+G24 -> 200
A42: Geotermia
A43: minihidro
A44: Central de falla
A45: Total | F45: =+SUM(F35:F44) -> 66428.94 | G45: =+SUM(G35:G44) -> 15059.48
A50: Problema 1- T2 | B50: ponderación problema | D50: 0.5 | G50: total tablas: 90%
G51: comente : 10%
A52: Tabla 1.1 Capacidad instalada (MW neto), con Norma
C55: 60 | D55: 22 | E55: 53
C56: MP-3,SOx-3 | D56: MP-2,SOx-2 | E56: MP-2 | F56: sin filtros | G56: sin filtros | H56: sin filtros | I56: sin filtros | J56: sin filtros | K56: sin filtros | L56: sin filtros | M56: sin filtros
A57: Ubicación | B57: Código | C57: Carbón 1 | D57: CC-GNL | E57: Diesel 1 | F57: Diesel 2 | G57: Biomasa | H57: Hidro | I57: Eolica | J57: Solar | K57: Geotermia | L57: minihidro | M57: Falla
A59: Diego de Almagro | B59: DAl | F59: =+VLOOKUP($B59,$C$16:$G$21,5,0) -> 439
...

Sheet preg2-Optima
A2: Tecnología | B2: filtro | C2: Localización | D2: Pot Exis MW | E2: Pot Nueva MW | F2: Gen GWh | G2: Pot total MW | K2: Tecnología | L2: filtro | M2: Localización | N2: Pot Exis MW | O2: Pot Nueva MW | P2: Gen GWh
A3: bio | B3: fil64 | C3: Ita | D3: 60 | E3: 0 | F3: 289.01 | G3: =+D3+E3 -> 60 | K3: bio | L3: fil64 | M3: Ita | N3: 60 | O3: 0 | P3: 289.01
A4: bio | B4: fil64 | C4: Cha | D4: 204 | E4: 0 | F4: 982.63 | G4: =+D4+E4 -> 204 | K4: bio | L4: fil64 | M4: Cha | N4: 204 | O4: 0 | P4: 1608.34
A5: car | B5: fil40 | C5: Qui | D5: 812 | E5: 0 | F5: 3824.33 | G5: =+D5+E5 -> 812 | K5: car | L5: fil40 | M5: Qui | N5: 812 | O5: 0 | P5: 3824.33
A6: car | B6: fil40 | C6: Cor | D6: 806 | E6: 0 | F6: 4023.46 | G6: =+D6+E6 -> 806 | K6: car | L6: fil40 | M6: Cor | N6: 806 | O6: 0 | P6: 6142.69
A7: car | B7: fil49 | C7: Hua | D7: 575 | E7: 0 | F7: 4432.56 | G7: =+D7+E7 -> 575 | K7: car | L7: fil53 | M7: Hua | N7: 575 | O7: 0 | P7: 4432.56
A8: car | B8: fil64 | C8: Hua | D8: 0 | E8: 2581.84 | F8: 19902.9 | G8: =+D8+E8 -> 2581.84 | K8: car | L8: fil64 | M8: Hua | N8: 0 | O8: 1485.25 | P8: 8779.53
A9: gas | B9: fil64 | C9: Qui | D9: 731 | E9: 0 | F9: 815.8 | G9: =+D9+E9 -> 731 | K9: gas | L9: fil64 | M9: Qui | N9: 731 | O9: 0 | P9: 815.8
A10: die | B10: fil64 | C10: car | D10: 169 | E10: 0 | F10: 0 | G10: =+D10+E10 -> 169 | K10: die | L10: fil64 | M10: car | N10: 169 | O10: 0 | P10: 0
A11: die | B11: fil64 | C11: DAl | D11: 439 | E11: 0 | F11: 0 | G11: =+D11+E11 -> 439 | K11: die | L11: fil64 | M11: DAl | N11: 439 | O11: 0 | P11: 0
A12: die | B12: fil64 | C12: Hua | D12: 58 | E12: 0 | F12: 0 | G12: =+D12+E12 -> 58 | K12: die | L12: fil64 | M12: Hua | N12: 58 | O12: 0 | P12: 0
A13: die | B13: fil64 | C13: PAz | D13: 97 | E13: 0 | F13: 0 | G13: =+D13+E13 -> 97 | K13: die | L13: fil64 | M13: PAz | N13: 97 | O13: 0 | P13: 0
A14: die | B14: fil64 | C14: LVi | D14: 203 | E14: 0 | F14: 0 | G14: =+D14+E14 -> 203 | K14: die | L14: fil64 | M14: LVi | N14: 203 | O14: 0 | P14: 0
... A23: eo1 | B23: fil64 | C23: LVi | D23: 192 | E23: 0 | F23: 420.48 | G23: =+D23+E23 -> 192 | K23: eol | L23: fil64 | M23: LVi | N23: 192 | O23: 0 | P23: 420.48
A24: so1 | B24: fil64 | C24: Hua | D24: 200 | E24: 0 | F24: 438 | G24: =+D24+E24 -> 200
F25: =+SUM(F3:F24) -> 66428.95 | G25: =+SUM(G3:G24) -> 15288.84
A27: mp Miles Ton | B27: sox Miles Ton | C27: nox Miles Ton | D27: co2 Miles Ton
A28: 66.43 | B28: 180.77 | C28: 54.25 | D28: 27174.05
A29: mp US$ | B29: sox US$ | C29: nox US$ | D29: co2 US$ | E29: Costo total US$ (incluye daño ambiental)
A30: 41863073 | B30: 51822614 | C30: 12069139 | D30: 0 | E30: 2160313400
F34: Gen GWh | G34: Pot total MW
A35: Biomasa | F35: =+F3+F4 -> 1271.64 | G35: =+G3+G4 -> 264
A36: Carbón | F36: =+SUM(F5:F8) -> 32183.25 | G36: =+SUM(G5:G8) -> 4774.84
A37: CC-GNL | F37: =+F9 -> 815.8 | G37: =+G9 -> 731
A38: Petróleo Diesel | F38: =+SUM(F10:F21) -> 2018.6 | G38: =+SUM(G10:G21) -> 3556
A39: Hidro | F39: =+F22 -> 29281.18 | G39: =+G22 -> 5571
A40: Eolica | F40: =+F23 -> 420.48 | G40: =+G23 -> 192
A41: Solar | F41: =+F24 -> 438 | G41: =+G24 -> 200
A42: Geotermia
A43: minihidro
A44: Central de falla
F45: =+SUM(F35:F44) -> 66428.95 | G45: =+SUM(G35:G44) -> 15288.84
A46: Total
A50: Problema 3 - I2 | B50: ponderación problema | D50: 0.5 | H50: total tablas: 90%
H51: comente : 10%
A52: Tabla 2.1 Capacidad instalada (MW neto), con política eficiente
B55: 40 | C55: 49 | D55: 64
B56: NOx-3, MP-2,SOx-2 | C56: MP-1 | D56: sin filtros | E56: sin filtros | F56: sin filtros | G56: sin filtros | H56: sin filtros | I56: sin filtros | J56: sin filtros | K56: sin filtros | L56: sin filtros | M56: sin filtros
A57: Ubicación | B57: Carbón 1 | C57: Carbón 2 | D57: Carbón 3 | E57: CC-GNLi | F57: Diesel i | G57: Biomasa | H57: Hidro | I57: Eolica | J57: Solar | K57: Geotermia | L57: minihidro | M57: Falla
A59: Diego de Almagro | F59: =+VLOOKUP($R59,$C$10:$G$21,5,0) -> 439 | R59: DAl
...

Sheet preg1 sin politica
A2: Tecnología | B2: filtro | C2: Localización | D2: Pot Exis MW | E2: Pot Nueva MW | F2: Gen GWh | G2: Pot total MW
A3: bio | B3: fil64 | C3: Ita | D3: 60 | E3: 0 | F3: 289.01 | G3: =+D3+E3 -> 60
A4: bio | B4: fil64 | C4: Cha | D4: 204 | E4: 0 | F4: 982.63 | G4: =+D4+E4 -> 204
A5: car | B5: fil64 | C5: Hua | D5: 575 | E5: 0 | F5: 4432.56 | G5: =+D5+E5 -> 575
A6: car | B6: fil64 | C6: Qui | D6: 812 | E6: 2581.84 | F6: 23727.22 | G6: =+D6+E6 -> 3393.84
A7: car | B7: fil64 | C7: Cor | D7: 806 | E7: 0 | F7: 4023.46 | G7: =+D7+E7 -> 806
A8: gas | B8: fil64 | C8: Qui | D8: 731 | E8: 0 | F8: 815.8 | G8: =+D8+E8 -> 731
A9: die | B9: fil64 | C9: car | D9: 169 | E9: 0 | F9: 0 | G9: =+D9+E9 -> 169
A10: die | B10: fil64 | C10: DAl | D10: 439 | E10: 0 | F10: 0 | G10: =+D10+E10 -> 439
A11: die | B11: fil64 | C11: Hua | D11: 58 | E11: 0 | F11: 0 | G11: =+D11+E11 -> 58
A12: die | B12: fil64 | C12: PAz | D12: 97 | E12: 0 | F12: 0 | G12: =+D12+E12 -> 97
A13: die | B13: fil64 | C13: LVi | D13: 203 | E13: 0 | F13: 94.33 | G13: =+D13+E13 -> 203
A14: die | B14: fil64 | C14: Qui | D14: 700 | E14: 0 | F14: 772.8 | G14: =+D14+E14 -> 700
... A23: so1 | B23: fil64 | C23: Hua | D23: 200 | E23: 0 | F23: 438 | G23: =+D23+E23 -> 200
F24: =+SUM(F2:F23) -> 66428.94 | G24: =+SUM(G2:G23) -> 15288.84
A26: mp Miles Ton | B26: sox Miles Ton | C26: nox Miles Ton | D26: co2 Miles Ton
A27: 253.49 | B27: 239.17 | C27: 98.86 | D27: 27174.34
A28: mp US$ | B28: sox US$ | C28: nox US$ | D28: co2 US$ | E28: Costo total US$ (no incluye daño ambiental)
A29: 6.1774998e+08 | B29: 3.2130128e+08 | C29: 1.5603473e+08 | D29: 0 | E29: 1817153900
F34: Gen GWh | G34: Pot total MW
A35: Biomasa | F35: =+F3+F4 -> 1271.64 | G35: =+G3+G4 -> 264
A36: Carbón | F36: =+SUM(F5:F7) -> 32183.24 | G36: =+SUM(G5:G7) -> 4774.84
A37: CC-GNL | F37: =+F8 -> 815.8 | G37: =+G8 -> 731
A38: Petróleo Diesel | F38: =+SUM(F9:F20) -> 2018.6 | G38: =+SUM(G9:G20) -> 3556
A39: Hidro | F39: =+F21 -> 29281.18 | G39: =+G21 -> 5571
A40: Eolica | F40: =+F22 -> 420.48 | G40: =+G22 -> 192
A41: Solar | F41: =+F23 -> 438 | G41: =+G23 -> 200
A42: Geotermia
A43: minihidro
A44: Central de falla
A46: Total | F46: =+SUM(F35:F44) -> 66428.94 | G46: =+SUM(G35:G44) -> 15288.84
A52: Tabla 1.1 Capacidad instalada (MW neto),
D56: sin filtros | E56: sin filtros | F56: sin filtros | G56: sin filtros | H56: sin filtros | I56: sin filtros | J56: sin filtros | K56: sin filtros | L56: sin filtros | M56: sin filtros
A57: Ubicación | D57: Carbón 3 | E57: CC-GNLi | F57: Diesel i | G57: Biomasa | H57: Hidro | I57: Eolica | J57: Solar | K57: Geotermia | L57: minihidro | M57: Falla
A59: Diego de Almagro | F59: =+VLOOKUP($R59,$C$9:$G$20,5,0) -> 439 | R59: DAl
A60: Cardones | F60: =+VLOOKUP($R60,$C$9:$G$20,5,0) -> 169 | R60: car
A61: Huasco | D61: =+VLOOKUP($R61,$C$5:$G$7,5,0) -> 575 | E61: =+G8 -> 731 | F61: =+VLOOKUP($R61,$C$9:$G$20,5,0) -> 58 | J61: =+G23 -> 200 | R61: Hua
A62: Pan de Azucar | F62: =+VLOOKUP($R62,$C$9:$G$20,5,0) -> 97 | R62: PAz
A63: Los Vilos | F63: =+VLOOKUP($R63,$C$9:$G$20,5,0) -> 203 | I63: =+G22 -> 192 | R63: LVi
A64: Quillota | D64: =+VLOOKUP($R64,$C$5:$G$7,5,0) -> 3393.84 | F64: =+VLOOKUP($R64,$C$9:$G$20,5,0) -> 700 | R64: Qui
...
